<?xml version="1.0"?>
<robot name="cepheus" xmlns:xacro="http://www.ros.org/wiki/xacro">
	<xacro:include filename="$(find cepheus_description)/urdf/cepheus.gazebo" />
	<xacro:include filename="$(find cepheus_description)/urdf/materials.xacro" />
	<xacro:property name="camera_link" value="0.05" /> <!-- Size of square 'camera' box -->
	<!--<link name="world">
		<joint name="world_joint" type="continuous">
			<axis xyz="0 0 1"/>
			<parent link="world"/>
			<origin rpy="0 0 0" xyz="0 0 0"/>
			<child link="cepheus"/>
			<dynamics damping="0" friction="0"/>
		</joint> 
	</link>-->

	<!-- extra links addition START -->
	<!-- <joint name="world_joint" type="continuous">
		<axis xyz="0 0 1"/>
		<parent link="world"/>
		<origin rpy="0 0 0" xyz="0 0 0"/>
		<child link="cepheus"/>
		<dynamics damping="0" friction="0"/>
	</joint> -->
	<link name = "world"/>

	<joint name="thrusterx_joint" type="prismatic">
		<parent link="world"/>
		<child link="p1"/>
		<axis xyz="1 0 0"/>
		<limit lower="-100" upper="100" effort="1000" velocity="10000"/>
		<dynamics damping="0" friction="0"/>
	</joint>
	<link name="p1">
		<inertial>
			<origin
				xyz="0.0 0.0 0.0"
				rpy="0.0 0.0 0.0" />
			<mass value="0.01" />
			<inertia
				ixx="1e-2"
				ixy="0.0"
				ixz="0.0"
				iyy="1e-2"
				iyz="0.0"
				izz="1e-2" />
		</inertial>
	</link>
	<gazebo reference="p1">
		<mu1>0</mu1>
		<mu2>0</mu2>
	</gazebo>
	<transmission name="lin1">
		<type>transmission_interface/SimpleTransmission</type>
		<joint name="thrusterx_joint">
			<hardwareInterface>hardware_interface/EffortJointInterface</hardwareInterface>
		</joint>
		<actuator name="lin_motor1">
			<hardwareInterface>EffortJointInterface</hardwareInterface>
			<mechanicalReduction>1</mechanicalReduction>
		</actuator>
	</transmission>
	<joint name="thrustery_joint" type="prismatic">
		<parent link="p1"/>
		<child link="cepheus_base"/>
		<axis xyz="0 1 0"/>
		<limit
			lower="-100"
			upper="100"
			effort="1000"
			velocity="10000"/>
		<dynamics
			damping="0"
			friction="0"/>
	</joint>
	<!-- <link name="p2">
		<inertial>
			<origin
				xyz="0.0 0.0 0.0"
				rpy="0.0 0.0 0.0" />
			<mass value="0.01" />
			<inertia
				ixx="1e-2"
				ixy="0.0"
				ixz="0.0"
				iyy="1e-2"
				iyz="0.0"
				izz="1e-2" />
		</inertial>
		<surface>
			<friction>
				<ode>
					<mu>0</mu>
					<mu2>0</mu2>
					<fdir1>0 1.0 0</fdir1>
					<implicit_spring_damper>true</implicit_spring_damper>
				</ode>
			</friction>
		</surface>
	</link>
	<gazebo reference="p2">
		<mu1>0</mu1>
		<mu2>0</mu2>
	</gazebo> -->
	<transmission name="lin2">
		<type>transmission_interface/SimpleTransmission</type>
		<joint name="thrustery_joint">
			<hardwareInterface>hardware_interface/EffortJointInterface</hardwareInterface>
		</joint>
		<actuator name="lin_motor2">
			<hardwareInterface>EffortJointInterface</hardwareInterface>
			<mechanicalReduction>1</mechanicalReduction>
		</actuator>
	</transmission>
	<!-- <joint name="p2_to_base" type="fixed">
		<parent link ="p2"/>
		<child link="cepheus_base"/>
	</joint> -->
	<!-- <joint name="r_joint" type="continuous">
		<axis xyz="0 0 1"/>
		<parent link="p2"/>
		<origin rpy="0 0 0" xyz="0 0 0"/>
		<child link="cepheus"/>
	</joint> -->
	<!-- extra links addition END -->
	<!-- <link name="world">
		<inertial>
			<origin
				xyz="0.00 0.0 0.0"
				rpy="0 0 0" />
			<mass value="10000" />
			<inertia
				ixx="0"
				ixy="0"
				ixz="0"
				iyy="0"
				iyz="0"
				izz="1000" />
		</inertial>
		<visual>
			<material name="LightGrey"/>
			<geometry>
				<box size="1000 1000 0.001"/>
			</geometry>
		</visual>
		<collision>
			<origin
				xyz="0 0 0"
				rpy="0 0 0" />
			<geometry>
				<box size="1000 1000 0.001"/>
			</geometry>
		</collision>
	</link> -->
	<!-- <joint name="thrusterx_joint" type="prismatic">
		<parent link="world"/>
		<child link="dummy_link"/>
		<origin xyz="0 0 0"/>
		<axis xyz="1 0 0"/>
		<limit lower="-100.0" upper="100.0" effort="10.0" velocity="1.0"/>
		<dynamics damping="1.0" />
	</joint>
		<link name="dummy_link">
		<inertial>
			<origin
				xyz="0.0 0.0 0.0"
				rpy="0 0 0" />
			<mass value="1" />
			<inertia
				ixx="0"
				ixy="0"
				ixz="0"
				iyy="0"
				iyz="0"
				izz="0.001" />
		</inertial>
		<visual>
			<material name="LightGrey"/>
			<geometry>
				<box size="0.001 0.001 0.001"/>
			</geometry>
		</visual>
		<collision>
			<origin
				xyz="0 0 0"
				rpy="0 0 0" />
			<geometry>
				<box size="0.001 0.001 0.001"/>
			</geometry>
		</collision>
	</link>
	<joint name="thrustery_joint" type="prismatic">
		<parent link="dummy_link"/>
		<child link="cepheus_base"/>
		<origin xyz="0 0 0"/>
		<axis xyz="0 1 0"/>
		<limit lower="-100.0" upper="100.0" effort="10.0" velocity="1.0"/>
		<dynamics damping="1.0" friction="1.0"/>
	</joint> -->
	<link name="cepheus_base">
		<inertial>
			<origin
				xyz="0.0024 0.02937 0.15711"
				rpy="0 0 0" />
			<mass value="400" />
			<inertia
				ixx="0"
				ixy="0"
				ixz="0"
				iyy="0"
				iyz="0"
				izz="200" />
		</inertial>
		<visual>
			<origin
				xyz="0 0 0"
				rpy="0 0 0" />
			<geometry>
				<mesh filename="package://cepheus_description/urdf/meshes/cepheus.STL" />
			</geometry>
			<material name="LightGrey"/>
		</visual>
		<collision>
			<origin
				xyz="0 0 0.215"
				rpy="0 0 0" />
			<geometry>
				<cylinder length="0.43" radius="0.2"/>
			</geometry>
		</collision>
	</link>
	<!-- <transmission name="tran0x">
		<type>
			transmission_interface/SimpleTransmission</type>
		<joint name="thrusterx_joint">
			<hardwareInterface>hardware_interface/EffortJointInterface</hardwareInterface>
		</joint>
		<actuator name="motor0x">
			<hardwareInterface>EffortJointInterface</hardwareInterface>
			<mechanicalReduction>1</mechanicalReduction>
		</actuator>
	</transmission>
	<transmission name="tran0y">
		<type>
			transmission_interface/SimpleTransmission</type>
		<joint name="thrustery_joint">
			<hardwareInterface>hardware_interface/EffortJointInterface</hardwareInterface>
		</joint>
		<actuator name="motor0y">
			<hardwareInterface>EffortJointInterface</hardwareInterface>
			<mechanicalReduction>1</mechanicalReduction>
		</actuator>
	</transmission> -->
	<joint name="reaction_wheel_joint" type="continuous">
		<parent link="cepheus_base"/>
		<child link="reaction_wheel"/>
		<origin xyz="0.065 0 0.03815" rpy="0 0 0"/>
		<axis xyz="0 0 1" />
	</joint>
	<link name="reaction_wheel">
		<visual>
			<material name="silver">
				<color rgba="0.5 0.5 0.5 1"/>
			</material>
			<geometry>
				<mesh filename="package://cepheus_description/urdf/meshes/reaction_wheel.STL" />
			</geometry>
			<origin xyz="0 0 0" rpy="0 0 0"/>
		</visual>
		<inertial>
			<origin xyz="0 0 0.025" rpy="0 0 0" />
			<mass value="1"/>
			<inertia
				ixx="0"
				ixy="0"
				ixz="0"
				iyy="0"
				iyz="0"
				izz="0.00197" />
		</inertial>
	</link>
	<gazebo reference="cepheus_base">
		<mu1>0</mu1>
		<mu2>0</mu2>
	</gazebo>
	<transmission name="tran1">
		<type>
			transmission_interface/SimpleTransmission</type>
		<joint name="reaction_wheel_joint">
			<hardwareInterface>hardware_interface/EffortJointInterface</hardwareInterface>
		</joint>
		<actuator name="motor1">
			<hardwareInterface>EffortJointInterface</hardwareInterface>
			<mechanicalReduction>1</mechanicalReduction>
		</actuator>
	</transmission>
	<joint name="left_shoulder_joint" type="revolute">
		<origin
			xyz="0.17271 0.091404 0.05875"
			rpy="0 0 0" />
		<parent link="cepheus_base" />
		<child link="left_arm" />
		<axis xyz="0 0 1" />
		<limit
			lower="-0.86"
			upper="2.54"
			effort="20"
			velocity="20" />
		<dynamics
			damping="1"
			friction="1" />
	</joint>
	<link name="left_arm">
		<inertial>
			<origin
				xyz="0.119 0 0"
				rpy="0 0 0" />
			<mass value="50" />
			<inertia
				ixx="0"
				ixy="0"
				ixz="0"
				iyy="0"
				iyz="0"
				izz="16.67" />
		</inertial>
		<visual>
			<origin
				xyz="0 -0.0085 0"
				rpy="0 0 0" />
			<geometry>
				<mesh filename="package://cepheus_description/urdf/meshes/left_arm.STL" />
			</geometry>
			<material name="LightGrey"/>
		</visual>
		<collision>
			<origin
				xyz="0.08 0.0 0.01"
				rpy="0 0 0" />
			<geometry>
				<box size="0.13 0.02 0.02"/>
			</geometry>
		</collision>
	</link>
	<transmission name="tran2">
		<type>transmission_interface/SimpleTransmission</type>
		<joint name="left_shoulder_joint">
			<hardwareInterface>hardware_interface/EffortJointInterface</hardwareInterface>
		</joint>
		<actuator name="motor2">
			<hardwareInterface>EffortJointInterface</hardwareInterface>
			<mechanicalReduction>1</mechanicalReduction>
		</actuator>
	</transmission>
	<joint name="left_elbow_joint" type="revolute">
		<origin
			xyz="0.1810 0 0"
			rpy="0 0 0" />
		<parent link="left_arm" />
		<child link="left_forearm" />
		<axis xyz="0 0 1" />
		<limit
			lower="-3.14"
			upper="1.5"
			effort="2"
			velocity="20" />
		<dynamics
			damping="1"
			friction="1" />
	</joint>
	<link name="left_forearm">
		<inertial>
			<origin
				xyz="0.119 0 0"
				rpy="0 0 0" />
			<mass value="50" />
			<inertia
				ixx="0"
				ixy="0"
				ixz="0"
				iyy="0"
				iyz="0"
				izz="16.67" />
		</inertial>
		<visual>
			<origin
				xyz="0 0 0"
				rpy="0 0 0" />
			<geometry>
				<mesh filename="package://cepheus_description/urdf/meshes/left_forearm.STL" />
			</geometry>
			<material name="LightGrey"/>
		</visual>
		<collision>
			<origin
				xyz="0.105 0.0115 0.0125"
				rpy="0 0 0" />
			<geometry>
				<box size="0.13 0.025 0.025"/>
			</geometry>
		</collision>
	</link>
	<transmission name="tran3">
		<type>transmission_interface/SimpleTransmission</type>
		<joint name="left_elbow_joint">
			<hardwareInterface>hardware_interface/EffortJointInterface</hardwareInterface>
		</joint>
		<actuator name="motor3">
			<hardwareInterface>EffortJointInterface</hardwareInterface>
			<mechanicalReduction>1</mechanicalReduction>
		</actuator>
	</transmission>
	<joint name="left_wrist_joint" type="revolute">
		<origin
			xyz="0.15965 0.01176 -0.00838"
			rpy="0 0 0 " />
		<parent link="left_forearm" />
		<child link="left_grip" />
		<axis xyz="0 0 1" />
		<limit
			lower="-1.570796327"
			upper="1.570796327"
			effort="10"
			velocity="10" />
		<dynamics
			damping="1"
			friction="1" />
	</joint>
	<link name="left_grip">
		<inertial>
			<origin
				xyz="0.01947 -0.00226 -0.00228"
				rpy="0 0 0" />
			<mass value="50" />
			<inertia
				ixx="0.0926325136613974"
				ixy="-0.00333421740190982"
				ixz="0.00529966557344093"
				iyy="0.0752633235560557"
				iyz="0.00191940596202769"
				izz="4.17" />
		</inertial>
		<visual>
			<origin
				xyz="0 0 0"
				rpy="1.5708 0 0"/>
			<geometry>
				<mesh filename="package://cepheus_description/urdf/meshes/left_grip.STL" />
			</geometry>
			<material name="LightGrey"/>
		</visual>
		<collision>
			<origin
				xyz="0.0375 0 0.022"
				rpy="1.5708 0 0" />
			<geometry>
				<box size="0.03 0.07 0.05"/>
			</geometry>
		</collision>

	</link> 
	<transmission name="tran4">
		<type>transmission_interface/SimpleTransmission</type>
		<joint name="left_wrist_joint">
			<hardwareInterface>hardware_interface/EffortJointInterface</hardwareInterface>
		</joint>
		<actuator name="motor4">
			<hardwareInterface>EffortJointInterface</hardwareInterface>
			<mechanicalReduction>1</mechanicalReduction>
		</actuator>
	</transmission>
	<!-- <joint name="camera_joint" type="fixed">
		<axis xyz="0 1 0" />
		<origin xyz="0 0 3.0" rpy="0 1.5708 1.5708"/>
		<parent link="world"/>
		<child link="camera_link"/>
	</joint> -->

	<!-- Camera -->
	<!-- <link name="camera_link">
		<collision>
			<origin xyz="0 0 0" rpy="0 0 0"/>
			<geometry>
				<box size="${camera_link} ${camera_link} ${camera_link}"/>
			</geometry>
		</collision>

		<visual>
			<origin xyz="0 0 0" rpy="0 0 0"/>
			<geometry>
				<box size="${camera_link} ${camera_link} ${camera_link}"/>
			</geometry>
			<material name="red"/>
		</visual>

		<inertial>
			<mass value="1e-5" />
			<origin xyz="0 0 0" rpy="0 0 0"/>
			<inertia ixx="1e-6" ixy="0" ixz="0" iyy="1e-6" iyz="0" izz="1e-6" />
		</inertial>
	</link> -->

	<!-- <gazebo reference="left_wrist_joint">
		<sensor name="left_wrist_joint_force_torque" type="force_torque">
    	<always_on>true</always_on>
    	<update_rate>20.0</update_rate>
    	<visualize>true</visualize>
    	<force_torque>
    		<frame>sensor</frame>
    		<measure_direction>child_to_parent</measure_direction>
    	</force_torque>
		</sensor>
	</gazebo> -->

<!-- The ft_sensor plugin -->  
	<!-- <gazebo>
		<plugin name="ft_sensor" filename="libgazebo_ros_ft_sensor.so">
			<alwaysOn>true</alwaysOn>
			<updateRate>10.0</updateRate>
			<topicName>ft_sensor_topic</topicName>
			<gaussianNoise>0.0</gaussianNoise>
			<jointName>left_wrist_joint</jointName>
			<visualize>true</visualize>
		</plugin> 
	</gazebo> -->

	<gazebo reference="left_wrist_joint">
		<disableFixedJointLumping>true</disableFixedJointLumping>
		<sensor name="my_cool_sensor" type="force_torque">
			<force_torque>
			<frame>child</frame>
			<measure_direction>child_to_parent</measure_direction>
			</force_torque>
		</sensor>
	</gazebo>
	<gazebo>
		<plugin name="ft_sensor" filename="libgazebo_ros_ft_sensor.so">
			<updateRate>0</updateRate>   <!--poly shmantiko na einai 0, allios kanei bug!!!!(nikhforos)-->
			<topicName>ft_sensor_topic</topicName>
			<jointName>left_wrist_joint</jointName>
		</plugin>
	</gazebo>
</robot>
